Workbook

Sheet Raw_Data
A1: DELIVERY_NAME | B1: DELIVERY_RATING | C1: MARKET_NUMBER | D1: MARKET_NAME | E1: TIMEZONE | F1: DASHER | G1: IS_FIRST_DELIVERY | H1: VEHICLE | I1: CREATED_AT | J1: QUOTED_DELIVERY_TIME | K1: ESTIMATED_DELIVERY_TIME | L1: ASAP | M1: FRAUDULENT | N1: ACTUAL_PICKUP_TIME | O1: ACTUAL_DELIVERY_TIME | P1: DASHER_ASSIGNED_TIME | Q1: MANUALLY_ASSIGNED | R1: DASHER_CONFIRMED_TIME | S1: DASHER_AT_STORE_TIME | T1: CANCELLED_AT | U1: ACTIVE_DATE | V1: COMPOSITE_SCORE | W1: SUBTOTAL | X1: CONFIRM_TO_DELIVER_DURATION | Y1: DASHER_TO_RESTAURANT_DURATION | Z1: DASHER_WAIT_DURATION | AA1: RESTAURANT_TO_CUSTOMER_DURATION | AB1: WAS_BATCHED | AC1: TOTAL_ITEM_COUNT | AD1: DASHER_TO_STORE_TIME_CATEGORY | AE1: ACTUAL_PICKUP_TIME_GALAXY_A | AF1: ACTUAL_DELIVERY_TIME_GALAXY_A | AG1: DASHER_ASSIGNED_TIME_GALAXY_A | AH1: DASHER_AT_STORE_TIME_GALAXY_A | AI1: COMPOSITE_STAR_RATING | AJ1: NUM_FIVE_STARS | AK1: NUM_DELIVERIES | AL1: NUM_ON_TIME_DELIVERIES
A2: 930 | B2: 5 | C2: 4050 | D2: Doorlanta | E2: Galaxy A | F2: Katelynn | G2: 0 | H2: car | I2: 2055-06-08T14:40:31.776158Z | J2: 2055-06-08T16:30:00Z | K2: 2055-06-08T16:30:00Z | L2: 0 | M2: 0 | N2: 2055-06-08T16:27:25.447059Z | O2: 2055-06-08T16:43:26.092195Z | P2: 2055-06-08T15:24:32.128072Z | Q2: 1 | R2: 2055-06-08T15:24:56.562443Z | U2: 56773 | V2: 4.5 | W2: 3000 | X2: 4710 | AA2: 961 | AB2: 0 | AC2: 47 | AE2: 2055-06-08T12:27:25.447059Z | AF2: 2055-06-08T12:43:26.092195Z | AG2: 2055-06-08T11:24:32.128072Z | AI2: 4.7 | AJ2: 1261 | AK2: 3264 | AL2: 232 | AM2: =AVERAGEIF(F:F, "Bill", V:V) -> 4.4312115
A3: 371 | C3: 4001 | D3: Dashattan | E3: Galaxy A | F3: Arya | G3: 0 | H3: bicycle | I3: 2055-06-03T23:55:23.345361Z | J3: 2055-06-04T02:10:19.438Z | K3: 2055-06-04T01:42:06.438Z | L3: 1 | M3: 0 | N3: 2055-06-04T00:43:45.908174Z | O3: 2055-06-04T01:08:26.640633Z | P3: 2055-06-04T00:30:14.629493Z | Q3: 1 | R3: 2055-06-04T00:30:30.006106Z | S3: 2055-06-04T00:38:02.90308Z | U3: 56768 | V3: 3.1984045 | W3: 2000 | X3: 2276 | Y3: 452 | Z3: 343 | AA3: 1481 | AB3: 0 | AC3: 10 | AD3: early | AE3: 2055-06-03T20:43:45.908174Z | AF3: 2055-06-03T21:08:26.640633Z | AG3: 2055-06-03T20:30:14.629493Z | AH3: 2055-06-03T20:38:02.90308Z | AI3: 4.17 | AJ3: 457 | AK3: 1599
A4: 1012 | B4: 5 | C4: 4001 | D4: Dashattan | E4: Galaxy A | F4: Bret | G4: 0 | H4: car | I4: 2055-06-09T13:45:44.022432Z | J4: 2055-06-09T15:29:57.082Z | K4: 2055-06-09T15:01:44.082Z | L4: 1 | M4: 1 | N4: 2055-06-09T15:11:25.372168Z | O4: 2055-06-09T15:13:35.539122Z | P4: 2055-06-09T14:04:34.144994Z | Q4: 0 | R4: 2055-06-09T14:05:28.008027Z | S4: 2055-06-09T14:19:12.351423Z | U4: 56774 | V4: 4.5 | W4: 1500 | X4: 4087 | Y4: 824 | Z4: 3133 | AA4: 130 | AB4: 0 | AC4: 22 | AD4: late | AE4: 2055-06-09T11:11:25.372168Z | AF4: 2055-06-09T11:13:35.539122Z | AG4: 2055-06-09T10:04:34.144994Z | AH4: 2055-06-09T10:19:12.351423Z | AI4: 3.82 | AJ4: 174 | AK4: 773
A5: 774 | C5: 4001 | D5: Dashattan | E5: Galaxy A | F5: Bret | G5: 0 | H5: car | I5: 2055-06-06T22:14:59.221376Z | J5: 2055-06-07T15:45:00Z | K5: 2055-06-07T15:45:00Z | L5: 0 | M5: 0 | N5: 2055-06-07T15:35:32.652626Z | O5: 2055-06-07T15:50:01.734136Z | P5: 2055-06-07T14:40:24.824381Z | Q5: 1 | R5: 2055-06-07T14:41:19.172553Z | S5: 2055-06-07T15:33:47.403919Z | U5: 56772 | V5: 4.5425218 | W5: 1500 | X5: 4122 | Y5: 3148 | Z5: 105 | AA5: 869 | AB5: 1 | AC5: 32 | AE5: 2055-06-07T11:35:32.652626Z | AF5: 2055-06-07T11:50:01.734136Z | AG5: 2055-06-07T10:40:24.824381Z | AH5: 2055-06-07T11:33:47.403919Z | AI5: 3.82 | AJ5: 174 | AK5: 773
A6: 412 | B6: 1 | C6: 4001 | D6: Dashattan | E6: Galaxy A | F6: Samm | G6: 0 | H6: car | I6: 2055-06-04T16:09:11.472458Z | J6: 2055-06-04T18:20:18.559Z | K6: 2055-06-04T18:20:18.559Z | L6: 0 | M6: 0 | N6: 2055-06-04T18:12:59.656413Z | O6: 2055-06-04T18:35:17.08753Z | P6: 2055-06-04T17:41:54.272943Z | Q6: 1 | R6: 2055-06-04T17:42:13.505934Z | S6: 2055-06-04T17:58:03.42043Z | U6: 56769 | V6: 4.3 | W6: 1500 | X6: 3184 | Y6: 950 | Z6: 896 | AA6: 1338 | AB6: 0 | AC6: 26 | AD6: early | AE6: 2055-06-04T14:12:59.656413Z | AF6: 2055-06-04T14:35:17.08753Z | AG6: 2055-06-04T13:41:54.272943Z | AH6: 2055-06-04T13:58:03.42043Z | AI6: 4.03 | AJ6: 505 | AK6: 1721 | AL6: 457
A7: 1050 | B7: 1 | C7: 4001 | D7: Dashattan | E7: Galaxy A | F7: Carlee | G7: 0 | H7: car | I7: 2055-06-09T19:49:41.693256Z | J7: 2055-06-10T15:45:00Z | K7: 2055-06-10T15:45:00Z | L7: 0 | M7: 0 | N7: 2055-06-10T15:18:09.540509Z | O7: 2055-06-10T15:23:08.754428Z | P7: 2055-06-10T14:47:54.187365Z | Q7: 0 | R7: 2055-06-10T14:48:06.628086Z | S7: 2055-06-10T15:10:46.951495Z | U7: 56775 | V7: 4.5425218 | W7: 1500 | X7: 2102 | Y7: 1360 | Z7: 443 | AA7: 299 | AB7: 0 | AC7: 20 | AD7: late | AE7: 2055-06-10T11:18:09.540509Z | AF7: 2055-06-10T11:23:08.754428Z | AG7: 2055-06-10T10:47:54.187365Z | AH7: 2055-06-10T11:10:46.951495Z | AI7: 4.52 | AJ7: 269 | AK7: 895 | AL7: 23
A8: 5 | B8: 5 | C8: 4050 | D8: Doorlanta | E8: Galaxy A | F8: Jagar | G8: 0 | H8: car | I8: 2055-06-01T14:26:36.995622Z | J8: 2055-06-01T16:00:00Z | K8: 2055-06-01T16:00:00Z | L8: 0 | M8: 0 | N8: 2055-06-01T15:41:52.41593Z | O8: 2055-06-01T15:52:44.442115Z | P8: 2055-06-01T15:00:07.376028Z | Q8: 0 | R8: 2055-06-01T15:00:16.289572Z | S8: 2055-06-01T15:11:29.739589Z | U8: 56766 | V8: 4.6 | W8: 1500 | X8: 3148 | Y8: 673 | Z8: 1823 | AA8: 652 | AB8: 0 | AC8: 15 | AD8: early | AE8: 2055-06-01T11:41:52.41593Z | AF8: 2055-06-01T11:52:44.442115Z | AG8: 2055-06-01T11:00:07.376028Z | AH8: 2055-06-01T11:11:29.739589Z | AI8: 4.89 | AJ8: 1778 | AK8: 5138 | AL8: 314
A9: 823 | B9: 5 | C9: 4001 | D9: Dashattan | E9: Galaxy A | F9: Samm | G9: 0 | H9: car | I9: 2055-06-07T12:29:58.490584Z | J9: 2055-06-07T23:15:00Z | K9: 2055-06-07T23:15:00Z | L9: 0 | M9: 0 | N9: 2055-06-07T23:06:49.039195Z | O9: 2055-06-07T23:07:04.529095Z | P9: 2055-06-07T22:18:34.346697Z | Q9: 0 | R9: 2055-06-07T22:18:39.784875Z | S9: 2055-06-07T22:33:52.326656Z | U9: 56772 | V9: 3.2420098 | W9: 1500 | X9: 2905 | Y9: 913 | Z9: 1977 | AA9: 15 | AB9: 0 | AC9: 6 | AD9: late | AE9: 2055-06-07T19:06:49.039195Z | AF9: 2055-06-07T19:07:04.529095Z | AG9: 2055-06-07T18:18:34.346697Z | AH9: 2055-06-07T18:33:52.326656Z | AI9: 4.03 | AJ9: 505 | AK9: 1721 | AL9: 457
A10: 275 | C10: 4001 | D10: Dashattan | E10: Galaxy A | F10: Samm | G10: 0 | H10: car | I10: 2055-06-03T15:49:29.798239Z | J10: 2055-06-03T17:14:45.888Z | K10: 2055-06-03T17:01:32.888Z | L10: 1 | M10: 0 | N10: 2055-06-03T16:37:12.215405Z | O10: 2055-06-03T16:51:15.79938Z | P10: 2055-06-03T16:05:14.936934Z | Q10: 0 | R10: 2055-06-03T16:05:22.620426Z | S10: 2055-06-03T16:32:42.302357Z | U10: 56768 | V10: 4.6 | W10: 1500 | X10: 2753 | Y10: 1640 | Z10: 270 | AA10: 843 | AB10: 0 | AC10: 10 | AD10: late | AE10: 2055-06-03T12:37:12.215405Z | AF10: 2055-06-03T12:51:15.79938Z | AG10: 2055-06-03T12:05:14.936934Z | AH10: 2055-06-03T12:32:42.302357Z | AI10: 4.03 | AJ10: 505 | AK10: 1721 | AL10: 457
A11: 3 | B11: 4 | C11: 4050 | D11: Doorlanta | E11: Galaxy A | F11: Sal | G11: 0 | H11: car | I11: 2055-06-01T14:19:19.004452Z | J11: 2055-06-01T16:00:00Z | K11: 2055-06-01T16:00:00Z | L11: 0 | M11: 0 | N11: 2055-06-01T15:54:40.489099Z | O11: 2055-06-01T16:10:40.273128Z | P11: 2055-06-01T15:00:07.351144Z | Q11: 0 | R11: 2055-06-01T15:00:15.282234Z | U11: 56766 | V11: 2.7238308 | W11: 1000 | X11: 4225 | AA11: 960 | AB11: 0 | AC11: 7 | AE11: 2055-06-01T11:54:40.489099Z | AF11: 2055-06-01T12:10:40.273128Z | AG11: 2055-06-01T11:00:07.351144Z | AI11: 4.46 | AJ11: 349 | AK11: 779
A12: 613 | B12: 5 | C12: 4050 | D12: Doorlanta | E12: Galaxy A | F12: Kev | G12: 1 | H12: car | I12: 2055-06-05T20:29:49.293908Z | J12: 2055-06-05T21:57:03.367Z | K12: 2055-06-05T21:36:56.367Z | L12: 1 | M12: 0 | N12: 2055-06-05T21:00:53.690836Z | O12: 2055-06-05T21:25:21.417903Z | P12: 2055-06-05T20:47:07.290523Z | Q12: 0 | R12: 2055-06-05T20:47:13.383317Z | S12: 2055-06-05T20:55:06.423426Z | U12: 56770 | V12: 4.7 | W12: 1000 | X12: 2288 | Y12: 473 | Z12: 347 | AA12: 1468 | AB12: 0 | AC12: 16 | AD12: late | AE12: 2055-06-05T17:00:53.690836Z | AF12: 2055-06-05T17:25:21.417903Z | AG12: 2055-06-05T16:47:07.290523Z | AH12: 2055-06-05T16:55:06.423426Z | AI12: 4.7407407 | AJ12: 43 | AK12: 144 | AL12: 80
A13: 718 | C13: 4050 | D13: Doorlanta | E13: Galaxy A | F13: Matt | G13: 0 | H13: car | I13: 2055-06-06T01:27:59.301958Z | J13: 2055-06-06T16:00:00Z | K13: 2055-06-06T16:00:00Z | L13: 0 | M13: 0 | N13: 2055-06-06T15:49:55.135794Z | O13: 2055-06-06T16:03:24.394424Z | P13: 2055-06-06T15:00:07.288126Z | Q13: 0 | R13: 2055-06-06T15:00:26.211274Z | S13: 2055-06-06T15:12:18.023155Z | U13: 56771 | V13: 4.5 | W13: 1000 | X13: 3778 | Y13: 712 | Z13: 2257 | AA13: 809 | AB13: 0 | AC13: 10 | AD13: early | AE13: 2055-06-06T11:49:55.135794Z | AF13: 2055-06-06T12:03:24.394424Z | AG13: 2055-06-06T11:00:07.288126Z | AH13: 2055-06-06T11:12:18.023155Z | AI13: 4.22 | AJ13: 1551 | AK13: 4625
A14: 927 | C14: 4050 | D14: Doorlanta | E14: Galaxy A | F14: Jagar | G14: 0 | H14: car | I14: 2055-06-08T14:23:46.742847Z | J14: 2055-06-08T16:30:00Z | K14: 2055-06-08T16:30:00Z | L14: 0 | M14: 0 | N14: 2055-06-08T16:02:19.598742Z | O14: 2055-06-08T16:11:42.561344Z | P14: 2055-06-08T15:30:27.401737Z | Q14: 0 | R14: 2055-06-08T15:30:38.403377Z | S14: 2055-06-08T15:39:54.411513Z | U14: 56773 | V14: 4.6 | W14: 1000 | X14: 2464 | Y14: 556 | Z14: 1345 | AA14: 563 | AB14: 0 | AC14: 10 | AD14: early | AE14: 2055-06-08T12:02:19.598742Z | AF14: 2055-06-08T12:11:42.561344Z | AG14: 2055-06-08T11:30:27.401737Z | AH14: 2055-06-08T11:39:54.411513Z | AI14: 4.89 | AJ14: 1778 | AK14: 5138 | AL14: 314
A15: 286 | B15: 3 | C15: 4050 | D15: Doorlanta | E15: Galaxy A | F15: Ash | G15: 0 | H15: car | I15: 2055-06-03T16:25:31.409567Z | J15: 2055-06-03T17:38:49.501Z | K15: 2055-06-03T17:19:10.501Z | L15: 1 | M15: 0 | N15: 2055-06-03T16:59:05.379588Z | O15: 2055-06-03T17:35:42.669252Z | P15: 2055-06-03T16:31:27.371306Z | Q15: 0 | R15: 2055-06-03T16:31:36.262896Z | U15: 56768 | V15: 4.5 | W15: 1000 | X15: 3846 | AA15: 2197 | AB15: 0 | AC15: 7 | AE15: 2055-06-03T12:59:05.379588Z | AF15: 2055-06-03T13:35:42.669252Z | AG15: 2055-06-03T12:31:27.371306Z | AI15: 4.66 | AJ15: 161 | AK15: 398
A16: 94 | B16: 5 | C16: 4050 | D16: Doorlanta | E16: Galaxy A | F16: Codee | G16: 0 | H16: car | I16: 2055-06-02T00:15:53.163656Z | J16: 2055-06-02T01:08:11.244Z | K16: 2055-06-02T01:07:32.244Z | L16: 1 | M16: 0 | N16: 2055-06-02T00:38:51.274164Z | O16: 2055-06-02T01:03:19.778995Z | P16: 2055-06-02T00:16:07.373744Z | Q16: 0 | R16: 2055-06-02T00:16:34.50453Z | S16: 2055-06-02T00:29:31.141773Z | U16: 56766 | V16: 4.8 | W16: 1000 | X16: 2805 | Y16: 777 | Z16: 560 | AA16: 1468 | AB16: 0 | AC16: 12 | AD16: on time | AE16: 2055-06-01T20:38:51.274164Z | AF16: 2055-06-01T21:03:19.778995Z | AG16: 2055-06-01T20:16:07.373744Z | AH16: 2055-06-01T20:29:31.141773Z | AI16: 4.3670886 | AJ16: 59 | AK16: 198 | AL16: 42
A17: 113 | C17: 4050 | D17: Doorlanta | E17: Galaxy A | F17: Lauran | G17: 0 | H17: car | I17: 2055-06-02T14:14:13.014128Z | J17: 2055-06-02T21:15:00Z | K17: 2055-06-02T21:15:00Z | L17: 0 | M17: 0 | N17: 2055-06-02T21:02:45.912741Z | O17: 2055-06-02T21:18:03.029991Z | P17: 2055-06-02T20:18:47.339647Z | Q17: 0 | R17: 2055-06-02T20:18:56.228585Z | S17: 2055-06-02T20:44:38.50371Z | U17: 56767 | V17: 4.5 | W17: 1000 | X17: 3547 | Y17: 1542 | Z17: 1087 | AA17: 918 | AB17: 0 | AC17: 6 | AD17: late | AE17: 2055-06-02T17:02:45.912741Z | AF17: 2055-06-02T17:18:03.029991Z | AG17: 2055-06-02T16:18:47.339647Z | AH17: 2055-06-02T16:44:38.50371Z | AI17: 4.42 | AJ17: 1396 | AK17: 4836 | AL17: 1278
A18: 207 | B18: 1 | C18: 4001 | D18: Dashattan | E18: Galaxy A | F18: Ron | G18: 0 | H18: bicycle | I18: 2055-06-02T23:27:56.045622Z | J18: 2055-06-03T00:30:14.101Z | K18: 2055-06-03T00:10:35.101Z | L18: 1 | M18: 0 | N18: 2055-06-03T00:05:32.024913Z | O18: 2055-06-03T00:25:35.591672Z | P18: 2055-06-02T23:32:55.244404Z | Q18: 0 | R18: 2055-06-02T23:33:18.91934Z | S18: 2055-06-02T23:50:54.342973Z | U18: 56767 | V18: 4.4 | W18: 1000 | X18: 3137 | Y18: 1056 | Z18: 878 | AA18: 1203 | AB18: 0 | AC18: 10 | AD18: on time | AE18: 2055-06-02T20:05:32.024913Z | AF18: 2055-06-02T20:25:35.591672Z | AG18: 2055-06-02T19:32:55.244404Z | AH18: 2055-06-02T19:50:54.342973Z | AI18: 4.56 | AJ18: 765 | AK18: 2618
A19: 973 | C19: 4001 | D19: Dashattan | E19: Galaxy A | F19: Bret | G19: 0 | H19: car | I19: 2055-06-08T22:02:05.357188Z | J19: 2055-06-09T16:00:00Z | K19: 2055-06-09T16:00:00Z | L19: 0 | M19: 0 | N19: 2055-06-09T15:44:54.492375Z | O19: 2055-06-09T16:01:06.092165Z | P19: 2055-06-09T15:13:54.322888Z | Q19: 0 | R19: 2055-06-09T15:14:40.504938Z | S19: 2055-06-09T15:41:42.317635Z | U19: 56774 | V19: 4.3 | W19: 1000 | X19: 2786 | Y19: 1622 | Z19: 192 | AA19: 972 | AB19: 1 | AC19: 8 | AE19: 2055-06-09T11:44:54.492375Z | AF19: 2055-06-09T12:01:06.092165Z | AG19: 2055-06-09T11:13:54.322888Z | AH19: 2055-06-09T11:41:42.317635Z | AI19: 3.82 | AJ19: 174 | AK19: 773
A20: 485 | C20: 4050 | D20: Doorlanta | E20: Galaxy A | F20: Katelynn | G20: 0 | H20: car | I20: 2055-06-04T23:16:19.806926Z | J20: 2055-06-05T00:13:30.868Z | K20: 2055-06-04T23:58:51.868Z | L20: 1 | M20: 0 | N20: 2055-06-04T23:55:02.638822Z | O20: 2055-06-05T00:05:54.873885Z | P20: 2055-06-04T23:16:27.662725Z | Q20: 0 | R20: 2055-06-04T23:17:04.516324Z | S20: 2055-06-04T23:24:47.340345Z | U20: 56769 | V20: 4.6 | W20: 1000 | X20: 2930 | Y20: 463 | Z20: 1815 | AA20: 652 | AB20: 0 | AC20: 6 | AD20: early | AE20: 2055-06-04T19:55:02.638822Z | AF20: 2055-06-04T20:05:54.873885Z | AG20: 2055-06-04T19:16:27.662725Z | AH20: 2055-06-04T19:24:47.340345Z | AI20: 4.7 | AJ20: 1261 | AK20: 3264 | AL20: 232
A21: 827 | C21: 4001 | D21: Dashattan | E21: Galaxy A | F21: Bret | G21: 0 | H21: car | I21: 2055-06-07T13:50:11.106486Z | J21: 2055-06-07T14:30:17.169Z | K21: 2055-06-07T14:21:24.169Z | L21: 1 | M21: 0 | N21: 2055-06-07T14:33:35.994888Z | O21: 2055-06-07T14:57:30.713153Z | P21: 2055-06-07T13:50:14.118263Z | Q21: 0 | R21: 2055-06-07T13:50:18.103263Z | S21: 2055-06-07T13:50:33.323279Z | U21: 56772 | V21: 4.5 | W21: 1000 | X21: 4032 | Y21: 15 | Z21: 2582 | AA21: 1435 | AB21: 1 | AC21: 19 | AE21: 2055-06-07T10:33:35.994888Z | AF21: 2055-06-07T10:57:30.713153Z | AG21: 2055-06-07T09:50:14.118263Z | AH21: 2055-06-07T09:50:33.323279Z | AI21: 3.82 | AJ21: 174 | AK21: 773
A22: 949 | B22: 1 | C22: 4050 | D22: Doorlanta | E22: Galaxy A | F22: Cate | G22: 0 | H22: car | I22: 2055-06-08T17:03:58.423933Z | J22: 2055-06-08T17:58:58.49Z | K22: 2055-06-08T17:31:17.49Z | L22: 1 | M22: 0 | N22: 2055-06-08T17:30:42.284657Z | O22: 2055-06-08T17:40:38.362483Z | P22: 2055-06-08T17:04:07.323219Z | Q22: 0 | R22: 2055-06-08T17:04:15.588968Z | S22: 2055-06-08T17:19:16.893874Z | U22: 56773 | V22: 4.6 | W22: 1000 | X22: 2183 | Y22: 901 | Z22: 686 | AA22: 596 | AB22: 0 | AC22: 13 | AD22: on time | AE22: 2055-06-08T13:30:42.284657Z | AF22: 2055-06-08T13:40:38.362483Z | AG22: 2055-06-08T13:04:07.323219Z | AH22: 2055-06-08T13:19:16.893874Z | AI22: 4.49 | AJ22: 2315 | AK22: 7039 | AL22: 763
A23: 4 | B23: 5 | C23: 4050 | D23: Doorlanta | E23: Galaxy A | F23: Matt | G23: 0 | H23: car | I23: 2055-06-01T14:23:25.582144Z | J23: 2055-06-01T15:18:25.659Z | K23: 2055-06-01T14:56:28.659Z | L23: 1 | M23: 0 | N23: 2055-06-01T15:42:29.641268Z | O23: 2055-06-01T15:57:28.896504Z | P23: 2055-06-01T14:25:07.246323Z | Q23: 0 | R23: 2055-06-01T14:25:22.663283Z | S23: 2055-06-01T15:31:06.908633Z | U23: 56766 | V23: 4.3 | W23: 1000 | X23: 5526 | Y23: 3944 | Z23: 683 | AA23: 899 | AB23: 0 | AC23: 11 | AD23: late | AE23: 2055-06-01T11:42:29.641268Z | AF23: 2055-06-01T11:57:28.896504Z | AG23: 2055-06-01T10:25:07.246323Z | AH23: 2055-06-01T11:31:06.908633Z | AI23: 4.22 | AJ23: 1551 | AK23: 4625
A24: 1551 | B24: 4 | C24: 4001 | D24: Dashattan | E24: Galaxy A | F24: Sean | G24: 0 | H24: bicycle | I24: 2055-06-13T14:37:39.095965Z | J24: 2055-06-13T16:15:00Z | K24: 2055-06-13T16:15:00Z | L24: 0 | M24: 0 | N24: 2055-06-13T15:31:18.826114Z | O24: 2055-06-13T15:36:20.851883Z | P24: 2055-06-13T15:15:34.266911Z | Q24: 0 | R24: 2055-06-13T15:16:02.345147Z | S24: 2055-06-13T15:20:48.907935Z | U24: 56778 | V24: 4.4 | W24: 1000 | X24: 1218 | Y24: 286 | Z24: 630 | AA24: 302 | AB24: 0 | AC24: 12 | AD24: early | AE24: 2055-06-13T11:31:18.826114Z | AF24: 2055-06-13T11:36:20.851883Z | AG24: 2055-06-13T11:15:34.266911Z | AH24: 2055-06-13T11:20:48.907935Z | AI24: 4.52 | AJ24: 183 | AK24: 522
A25: 742 | C25: 4050 | D25: Doorlanta | E25: Galaxy A | F25: Katelynn | G25: 0 | H25: car | I25: 2055-06-06T16:41:15.731402Z | J25: 2055-06-06T17:46:09.803Z | K25: 2055-06-06T17:24:15.803Z | L25: 1 | M25: 0 | N25: 2055-06-06T17:22:53.925846Z | O25: 2055-06-06T17:44:01.921308Z | P25: 2055-06-06T16:51:07.274373Z | Q25: 0 | R25: 2055-06-06T16:51:11.550738Z | S25: 2055-06-06T17:08:32.499641Z | U25: 56771 | V25: 4.5 | W25: 1000 | X25: 3170 | Y25: 1041 | Z25: 861 | AA25: 1268 | AB25: 0 | AC25: 14 | AD25: late | AE25: 2055-06-06T13:22:53.925846Z | AF25: 2055-06-06T13:44:01.921308Z | AG25: 2055-06-06T12:51:07.274373Z | AH25: 2055-06-06T13:08:32.499641Z | AI25: 4.7 | AJ25: 1261 | AK25: 3264 | AL25: 232
A26: 361 | B26: 3 | C26: 4050 | D26: Doorlanta | E26: Galaxy A | F26: Lauran | G26: 0 | H26: car | I26: 2055-06-03T23:15:25.883303Z | J26: 2055-06-04T00:16:53.959Z | K26: 2055-06-03T23:58:00.959Z | L26: 1 | M26: 0 | N26: 2055-06-03T23:59:19.549565Z | O26: 2055-06-04T00:15:50.983126Z | P26: 2055-06-03T23:15:47.365112Z | Q26: 0 | R26: 2055-06-03T23:15:52.523686Z | S26: 2055-06-03T23:21:10.238683Z | U26: 56768 | V26: 4.5 | W26: 1000 | X26: 3598 | Y26: 318 | Z26: 2289 | AA26: 991 | AB26: 0 | AC26: 4 | AD26: early | AE26: 2055-06-03T19:59:19.549565Z | AF26: 2055-06-03T20:15:50.983126Z | AG26: 2055-06-03T19:15:47.365112Z | AH26: 2055-06-03T19:21:10.238683Z | AI26: 4.42 | AJ26: 1396 | AK26: 4836 | AL26: 1278
A27: 36 | C27: 4001 | D27: Dashattan | E27: Galaxy A | F27: KC | G27: 0 | H27: car | I27: 2055-06-01T21:01:04.209755Z | J27: 2055-06-02T15:30:00Z | K27: 2055-06-02T15:30:00Z | L27: 0 | M27: 0 | N27: 2055-06-02T14:48:48.937943Z | O27: 2055-06-02T15:08:40.224318Z | P27: 2055-06-02T14:30:14.230927Z | Q27: 0 | R27: 2055-06-02T14:30:28.58113Z | S27: 2055-06-02T14:41:27.462278Z | U27: 56767 | V27: 4.4 | W27: 1000 | X27: 2292 | Y27: 659 | Z27: 441 | AA27: 1192 | AB27: 0 | AC27: 11 | AD27: on time | AE27: 2055-06-02T10:48:48.937943Z | AF27: 2055-06-02T11:08:40.224318Z | AG27: 2055-06-02T10:30:14.230927Z | AH27: 2055-06-02T10:41:27.462278Z | AI27: 4.54 | AJ27: 2229 | AK27: 6580
A28: 271 | C28: 4001 | D28: Dashattan | E28: Galaxy A | F28: Sean | G28: 0 | H28: bicycle | I28: 2055-06-03T15:44:35.396375Z | J28: 2055-06-03T16:22:42.451Z | K28: 2055-06-03T16:13:49.451Z | L28: 1 | M28: 0 | N28: 2055-06-03T17:27:07.724355Z | O28: 2055-06-03T17:39:52.518053Z | P28: 2055-06-03T17:09:14.942128Z | Q28: 0 | R28: 2055-06-03T17:09:44.546634Z | S28: 2055-06-03T17:11:59.817956Z | U28: 56768 | V28: 3.4933989 | W28: 7500 | X28: 1808 | Y28: 135 | Z28: 908 | AA28: 765 | AB28: 1 | AC28: 13 | AE28: 2055-06-03T13:27:07.724355Z | AF28: 2055-06-03T13:39:52.518053Z | AG28: 2055-06-03T13:09:14.942128Z | AH28: 2055-06-03T13:11:59.817956Z | AI28: 4.52 | AJ28: 183 | AK28: 522
A29: 498 | C29: 4050 | D29: Doorlanta | E29: Galaxy A | F29: Josh | G29: 0 | H29: car | I29: 2055-06-04T23:56:30.589599Z | J29: 2055-06-05T00:50:13.651Z | K29: 2055-06-05T00:35:32.651Z | L29: 1 | M29: 0 | N29: 2055-06-05T00:26:50.434556Z | O29: 2055-06-05T00:39:33.904762Z | P29: 2055-06-05T00:06:07.281382Z | Q29: 0 | R29: 2055-06-05T00:06:15.726482Z | S29: 2055-06-05T00:14:42.058012Z | U29: 56769 | V29: 3.4317833 | W29: 7500 | X29: 1998 | Y29: 507 | Z29: 728 | AA29: 763 | AB29: 1 | AC29: 5 | AE29: 2055-06-04T20:26:50.434556Z | AF29: 2055-06-04T20:39:33.904762Z | AG29: 2055-06-04T20:06:07.281382Z | AH29: 2055-06-04T20:14:42.058012Z | AI29: 4.77 | AJ29: 426 | AK29: 1226 | AL29: 85
A30: 731 | B30: 5 | C30: 4050 | D30: Doorlanta | E30: Galaxy A | F30: Jagar | G30: 0 | H30: car | I30: 2055-06-06T15:49:17.745982Z | J30: 2055-06-06T16:44:17.827Z | K30: 2055-06-06T16:21:45.827Z | L30: 1 | M30: 0 | N30: 2055-06-06T16:26:31.887028Z | O30: 2055-06-06T16:34:36.268071Z | P30: 2055-06-06T15:49:27.327972Z | Q30: 0 | R30: 2055-06-06T15:49:37.74976Z | S30: 2055-06-06T15:53:49.370735Z | U30: 56771 | V30: 4.6 | W30: 7500 | X30: 2699 | Y30: 252 | Z30: 1962 | AA30: 485 | AB30: 0 | AC30: 8 | AD30: early | AE30: 2055-06-06T12:26:31.887028Z | AF30: 2055-06-06T12:34:36.268071Z | AG30: 2055-06-06T11:49:27.327972Z | AH30: 2055-06-06T11:53:49.370735Z | AI30: 4.89 | AJ30: 1778 | AK30: 5138 | AL30: 314
A31: 639 | C31: 4050 | D31: Doorlanta | E31: Galaxy A | F31: Abhai | G31: 0 | H31: car | I31: 2055-06-05T22:05:58.809237Z | J31: 2055-06-05T22:58:56.877Z | K31: 2055-06-05T22:48:49.877Z | L31: 1 | M31: 0 | N31: 2055-06-05T22:25:00.638806Z | O31: 2055-06-05T22:40:12.579445Z | P31: 2055-06-05T22:06:07.487224Z | Q31: 0 | R31: 2055-06-05T22:06:14.092196Z | S31: 2055-06-05T22:08:57.772749Z | U31: 56770 | V31: 4.7 | W31: 7500 | X31: 2038 | Y31: 163 | Z31: 963 | AA31: 912 | AB31: 0 | AC31: 10 | AD31: early | AE31: 2055-06-05T18:25:00.638806Z | AF31: 2055-06-05T18:40:12.579445Z | AG31: 2055-06-05T18:06:07.487224Z | AH31: 2055-06-05T18:08:57.772749Z | AI31: 4.56 | AJ31: 344 | AK31: 947 | AL31: 22
A32: 253 | B32: 5 | C32: 4001 | D32: Dashattan | E32: Galaxy A | F32: Sean | G32: 0 | H32: bicycle | I32: 2055-06-03T13:56:31.072849Z | J32: 2055-06-03T15:45:00Z | K32: 2055-06-03T15:45:00Z | L32: 0 | M32: 0 | N32: 2055-06-03T15:26:48.122122Z | O32: 2055-06-03T15:34:24.487833Z | P32: 2055-06-03T14:50:14.204932Z | Q32: 0 | R32: 2055-06-03T14:50:52.366967Z | S32: 2055-06-03T14:56:31.525702Z | U32: 56768 | V32: 4.5 | W32: 7500 | X32: 2612 | Y32: 339 | Z32: 1817 | AA32: 456 | AB32: 0 | AC32: 18 | AD32: on time | AE32: 2055-06-03T11:26:48.122122Z | AF32: 2055-06-03T11:34:24.487833Z | AG32: 2055-06-03T10:50:14.204932Z | AH32: 2055-06-03T10:56:31.525702Z | AI32: 4.52 | AJ32: 183 | AK32: 522
A33: 966 | C33: 4001 | D33: Dashattan | E33: Galaxy A | F33: Rojan | G33: 0 | H33: bicycle | I33: 2055-06-08T21:23:31.277345Z | J33: 2055-06-08T22:00:49.324Z | K33: 2055-06-08T21:55:42.324Z | L33: 1 | M33: 0 | N33: 2055-06-08T21:57:43.670453Z | O33: 2055-06-08T22:15:15.322664Z | P33: 2055-06-08T21:29:34.38399Z | Q33: 0 | R33: 2055-06-08T21:29:57.51361Z | S33: 2055-06-08T21:46:00.732833Z | U33: 56773 | V33: 4.678193 | W33: 7500 | X33: 2718 | Y33: 963 | Z33: 703 | AA33: 1052 | AB33: 0 | AC33: 7 | AD33: late | AE33: 2055-06-08T17:57:43.670453Z | AF33: 2055-06-08T18:15:15.322664Z | AG33: 2055-06-08T17:29:34.38399Z | AH33: 2055-06-08T17:46:00.732833Z | AI33: 4.58 | AJ33: 254 | AK33: 788 | AL33: 9
A34: 1448 | B34: 5 | C34: 4001 | D34: Dashattan | E34: Galaxy A | F34: KC | G34: 0 | H34: car | I34: 2055-06-12T20:55:40.497868Z | J34: 2055-06-12T21:58:09.551Z | K34: 2055-06-12T21:39:16.551Z | L34: 1 | M34: 1 | N34: 2055-06-12T21:30:24.37677Z | O34: 2055-06-12T21:37:36.409707Z | P34: 2055-06-12T20:55:54.415667Z | Q34: 0 | R34: 2055-06-12T20:56:21.054655Z | S34: 2055-06-12T21:00:45.112963Z | U34: 56777 | V34: 3.4125151 | W34: 7500 | X34: 2475 | Y34: 264 | Z34: 1779 | AA34: 432 | AB34: 0 | AC34: 23 | AD34: early | AE34: 2055-06-12T17:30:24.37677Z | AF34: 2055-06-12T17:37:36.409707Z | AG34: 2055-06-12T16:55:54.415667Z | AH34: 2055-06-12T17:00:45.112963Z | AI34: 4.54 | AJ34: 2229 | AK34: 6580
A35: 252 | C35: 4001 | D35: Dashattan | E35: Galaxy A | F35: KC | G35: 0 | H35: car | I35: 2055-06-03T13:53:40.299682Z | J35: 2055-06-03T14:35:59.38Z | K35: 2055-06-03T14:26:20.38Z | L35: 1 | M35: 0 | N35: 2055-06-03T14:24:22.267753Z | O35: 2055-06-03T14:41:08.49135Z | P35: 2055-06-03T14:00:19.017871Z | Q35: 1 | R35: 2055-06-03T14:00:36.072249Z | S35: 2055-06-03T14:11:10.316031Z | U35: 56768 | V35: 4.5 | W35: 7500 | X35: 2432 | Y35: 634 | Z35: 792 | AA35: 1006 | AB35: 1 | AC35: 16 | AE35: 2055-06-03T10:24:22.267753Z | AF35: 2055-06-03T10:41:08.49135Z | AG35: 2055-06-03T10:00:19.017871Z | AH35: 2055-06-03T10:11:10.316031Z | AI35: 4.54 | AJ35: 2229 | AK35: 6580
A36: 349 | B36: 5 | C36: 4050 | D36: Doorlanta | E36: Galaxy A | F36: Anisha | G36: 0 | H36: car | I36: 2055-06-03T22:33:56.344997Z | J36: 2055-06-03T23:36:22.418Z | K36: 2055-06-03T23:17:29.418Z | L36: 1 | M36: 0 | N36: 2055-06-03T22:56:12.623884Z | O36: 2055-06-03T23:12:59.845577Z | P36: 2055-06-03T22:34:07.37549Z | Q36: 0 | R36: 2055-06-03T22:34:12.598085Z | U36: 56768 | V36: 4.8 | W36: 7500 | X36: 2327 | AA36: 1007 | AB36: 0 | AC36: 17 | AE36: 2055-06-03T18:56:12.623884Z | AF36: 2055-06-03T19:12:59.845577Z | AG36: 2055-06-03T18:34:07.37549Z | AI36: 4.7 | AJ36: 272 | AK36: 931 | AL36: 144
A37: 528 | B37: 5 | C37: 4050 | D37: Doorlanta | E37: Galaxy A | F37: Cate | G37: 0 | H37: car | I37: 2055-06-05T01:34:44.099926Z | J37: 2055-06-05T02:29:44.21Z | K37: 2055-06-05T02:08:26.21Z | L37: 1 | M37: 0 | N37: 2055-06-05T02:11:24.746754Z | O37: 2055-06-05T02:23:03.370921Z | P37: 2055-06-05T01:44:47.367076Z | Q37: 0 | R37: 2055-06-05T01:44:51.191099Z | S37: 2055-06-05T02:05:03.516913Z | U37: 56769 | V37: 4.6 | W37: 7500 | X37: 2292 | Y37: 1212 | Z37: 381 | AA37: 699 | AB37: 0 | AC37: 7 | AD37: late | AE37: 2055-06-04T22:11:24.746754Z | AF37: 2055-06-04T22:23:03.370921Z | AG37: 2055-06-04T21:44:47.367076Z | AH37: 2055-06-04T22:05:03.516913Z | AI37: 4.49 | AJ37: 2315 | AK37: 7039 | AL37: 763
A38: 104 | C38: 4001 | D38: Dashattan | E38: Galaxy A | F38: Arya | G38: 0 | H38: bicycle | I38: 2055-06-02T01:20:42.291878Z | J38: 2055-06-02T02:10:22.35Z | K38: 2055-06-02T01:55:43.35Z | L38: 1 | M38: 0 | N38: 2055-06-02T01:43:03.031108Z | O38: 2055-06-02T01:51:41.123571Z | P38: 2055-06-02T01:26:54.526136Z | Q38: 0 | R38: 2055-06-02T01:27:36.185254Z | S38: 2055-06-02T01:38:52.584896Z | U38: 56766 | V38: 2.6975186 | W38: 7500 | X38: 1445 | Y38: 676 | Z38: 251 | AA38: 518 | AB38: 0 | AC38: 4 | AD38: on time | AE38: 2055-06-01T21:43:03.031108Z | AF38: 2055-06-01T21:51:41.123571Z | AG38: 2055-06-01T21:26:54.526136Z | AH38: 2055-06-01T21:38:52.584896Z | AI38: 4.17 | AJ38: 457 | AK38: 1599
A39: 195 | B39: 5 | C39: 4050 | D39: Doorlanta | E39: Galaxy A | F39: Hersh | G39: 0 | H39: car | I39: 2055-06-02T22:48:18.7991Z | J39: 2055-06-02T23:43:19.081Z | K39: 2055-06-02T23:22:19.081Z | L39: 1 | M39: 0 | N39: 2055-06-02T23:17:56.920722Z | O39: 2055-06-02T23:32:21.439285Z | P39: 2055-06-02T22:48:27.483323Z | Q39: 0 | R39: 2055-06-02T22:48:38.091622Z | S39: 2055-06-02T23:02:03.903694Z | U39: 56767 | V39: 4.7 | W39: 7500 | X39: 2623 | Y39: 805 | Z39: 953 | AA39: 865 | AB39: 0 | AC39: 5 | AD39: on time | AE39: 2055-06-02T19:17:56.920722Z | AF39: 2055-06-02T19:32:21.439285Z | AG39: 2055-06-02T18:48:27.483323Z | AH39: 2055-06-02T19:02:03.903694Z | AI39: 4.7 | AJ39: 212 | AK39: 624 | AL39: 347
A40: 735 | B40: 1 | C40: 4001 | D40: Dashattan | E40: Galaxy A | F40: Rojan | G40: 0 | H40: bicycle | I40: 2055-06-06T16:05:07.268663Z | J40: 2055-06-10T15:30:00Z | K40: 2055-06-10T15:30:00Z | L40: 0 | M40: 0 | N40: 2055-06-10T14:44:52.018664Z | O40: 2055-06-10T14:55:28.739002Z | P40: 2055-06-10T14:31:54.182274Z | Q40: 0 | R40: 2055-06-10T14:32:02.882878Z | S40: 2055-06-10T14:36:50.807189Z | U40: 56775 | V40: 4.5 | W40: 7500 | X40: 1406 | Y40: 288 | Z40: 482 | AA40: 636 | AB40: 0 | AC40: 6 | AD40: early | AE40: 2055-06-10T10:44:52.018664Z | AF40: 2055-06-10T10:55:28.739002Z | AG40: 2055-06-10T10:31:54.182274Z | AH40: 2055-06-10T10:36:50.807189Z | AI40: 4.58 | AJ40: 254 | AK40: 788 | AL40: 9
...

Sheet Data_Cleaning
A1: =IFERROR(__xludf.DUMMYFUNCTION("FILTER(Raw_Data!A:AL, Raw_Data!A:A <> """")"),"DELIVERY_NAME") -> DELIVERY_NAME | B1: =IFERROR(__xludf.DUMMYFUNCTION("""COMPUTED_VALUE"""),"DELIVERY_RATING") -> DELIVERY_RATING | C1: =IFERROR(__xludf.DUMMYFUNCTION("""COMPUTED_VALUE"""),"MARKET_NUMBER") -> MARKET_NUMBER | D1: =IFERROR(__xludf.DUMMYFUNCTION("""COMPUTED_VALUE"""),"MARKET_NAME") -> MARKET_NAME | E1: =IFERROR(__xludf.DUMMYFUNCTION("""COMPUTED_VALUE"""),"TIMEZONE") -> TIMEZONE | F1: =IFERROR(__xludf.DUMMYFUNCTION("""COMPUTED_VALUE"""),"DASHER") -> DASHER | G1: =IFERROR(__xludf.DUMMYFUNCTION("""COMPUTED_VALUE"""),"IS_FIRST_DELIVERY") -> IS_FIRST_DELIVERY | H1: =IFERROR(__xludf.DUMMYFUNCTION("""COMPUTED_VALUE"""),"VEHICLE") -> VEHICLE | I1: =IFERROR(__xludf.DUMMYFUNCTION("""COMPUTED_VALUE"""),"CREATED_AT") -> CREATED_AT | J1: =IFERROR(__xludf.DUMMYFUNCTION("""COMPUTED_VALUE"""),"QUOTED_DELIVERY_TIME") -> QUOTED_DELIVERY_TIME | K1: =IFERROR(__xludf.DUMMYFUNCTION("""COMPUTED_VALUE"""),"ESTIMATED_DELIVERY_TIME") -> ESTIMATED_DELIVERY_TIME | L1: =IFERROR(__xludf.DUMMYFUNCTION("""COMPUTED_VALUE"""),"ASAP") -> ASAP | M1: =IFERROR(__xludf.DUMMYFUNCTION("""COMPUTED_VALUE"""),"FRAUDULENT") -> FRAUDULENT | N1: =IFERROR(__xludf.DUMMYFUNCTION("""COMPUTED_VALUE"""),"ACTUAL_PICKUP_TIME") -> ACTUAL_PICKUP_TIME | O1: =IFERROR(__xludf.DUMMYFUNCTION("""COMPUTED_VALUE"""),"ACTUAL_DELIVERY_TIME") -> ACTUAL_DELIVERY_TIME | P1: =IFERROR(__xludf.DUMMYFUNCTION("""COMPUTED_VALUE"""),"DASHER_ASSIGNED_TIME") -> DASHER_ASSIGNED_TIME | Q1: =IFERROR(__xludf.DUMMYFUNCTION("""COMPUTED_VALUE"""),"MANUALLY_ASSIGNED") -> MANUALLY_ASSIGNED | R1: =IFERROR(__xludf.DUMMYFUNCTION("""COMPUTED_VALUE"""),"DASHER_CONFIRMED_TIME") -> DASHER_CONFIRMED_TIME | S1: =IFERROR(__xludf.DUMMYFUNCTION("""COMPUTED_VALUE"""),"DASHER_AT_STORE_TIME") -> DASHER_AT_STORE_TIME | T1: =IFERROR(__xludf.DUMMYFUNCTION("""COMPUTED_VALUE"""),"CANCELLED_AT") -> CANCELLED_AT | U1: =IFERROR(__xludf.DUMMYFUNCTION("""COMPUTED_VALUE"""),"ACTIVE_DATE") -> ACTIVE_DATE | V1: =IFERROR(__xludf.DUMMYFUNCTION("""COMPUTED_VALUE"""),"COMPOSITE_SCORE") -> COMPOSITE_SCORE | W1: =IFERROR(__xludf.DUMMYFUNCTION("""COMPUTED_VALUE"""),"SUBTOTAL") -> SUBTOTAL | X1: =IFERROR(__xludf.DUMMYFUNCTION("""COMPUTED_VALUE"""),"CONFIRM_TO_DELIVER_DURATION") -> CONFIRM_TO_DELIVER_DURATION | Y1: =IFERROR(__xludf.DUMMYFUNCTION("""COMPUTED_VALUE"""),"DASHER_TO_RESTAURANT_DURATION") -> DASHER_TO_RESTAURANT_DURATION | Z1: =IFERROR(__xludf.DUMMYFUNCTION("""COMPUTED_VALUE"""),"DASHER_WAIT_DURATION") -> DASHER_WAIT_DURATION | AA1: =IFERROR(__xludf.DUMMYFUNCTION("""COMPUTED_VALUE"""),"RESTAURANT_TO_CUSTOMER_DURATION") -> RESTAURANT_TO_CUSTOMER_DURATION | AB1: =IFERROR(__xludf.DUMMYFUNCTION("""COMPUTED_VALUE"""),"WAS_BATCHED") -> WAS_BATCHED | AC1: =IFERROR(__xludf.DUMMYFUNCTION("""COMPUTED_VALUE"""),"TOTAL_ITEM_COUNT") -> TOTAL_ITEM_COUNT | AD1: =IFERROR(__xludf.DUMMYFUNCTION("""COMPUTED_VALUE"""),"DASHER_TO_STORE_TIME_CATEGORY") -> DASHER_TO_STORE_TIME_CATEGORY | AE1: =IFERROR(__xludf.DUMMYFUNCTION("""COMPUTED_VALUE"""),"ACTUAL_PICKUP_TIME_GALAXY_A") -> ACTUAL_PICKUP_TIME_GALAXY_A | AF1: =IFERROR(__xludf.DUMMYFUNCTION("""COMPUTED_VALUE"""),"ACTUAL_DELIVERY_TIME_GALAXY_A") -> ACTUAL_DELIVERY_TIME_GALAXY_A | AG1: =IFERROR(__xludf.DUMMYFUNCTION("""COMPUTED_VALUE"""),"DASHER_ASSIGNED_TIME_GALAXY_A") -> DASHER_ASSIGNED_TIME_GALAXY_A | AH1: =IFERROR(__xludf.DUMMYFUNCTION("""COMPUTED_VALUE"""),"DASHER_AT_STORE_TIME_GALAXY_A") -> DASHER_AT_STORE_TIME_GALAXY_A | AI1: =IFERROR(__xludf.DUMMYFUNCTION("""COMPUTED_VALUE"""),"COMPOSITE_STAR_RATING") -> COMPOSITE_STAR_RATING | AJ1: =IFERROR(__xludf.DUMMYFUNCTION("""COMPUTED_VALUE"""),"NUM_FIVE_STARS") -> NUM_FIVE_STARS | AK1: =IFERROR(__xludf.DUMMYFUNCTION("""COMPUTED_VALUE"""),"NUM_DELIVERIES") -> NUM_DELIVERIES | AL1: =IFERROR(__xludf.DUMMYFUNCTION("""COMPUTED_VALUE"""),"NUM_ON_TIME_DELIVERIES") -> NUM_ON_TIME_DELIVERIES
A2: =IFERROR(__xludf.DUMMYFUNCTION("""COMPUTED_VALUE"""),930) -> 930 | B2: =IFERROR(__xludf.DUMMYFUNCTION("""COMPUTED_VALUE"""),5) -> 5 | C2: =IFERROR(__xludf.DUMMYFUNCTION("""COMPUTED_VALUE"""),4050) -> 4050 | D2: =IFERROR(__xludf.DUMMYFUNCTION("""COMPUTED_VALUE"""),"Doorlanta") -> Doorlanta | E2: =IFERROR(__xludf.DUMMYFUNCTION("""COMPUTED_VALUE"""),"Galaxy A") -> Galaxy A | F2: =IFERROR(__xludf.DUMMYFUNCTION("""COMPUTED_VALUE"""),"Katelynn") -> Katelynn | G2: =IFERROR(__xludf.DUMMYFUNCTION("""COMPUTED_VALUE"""),0) -> 0 | H2: =IFERROR(__xludf.DUMMYFUNCTION("""COMPUTED_VALUE"""),"car") -> car | I2: =IFERROR(__xludf.DUMMYFUNCTION("""COMPUTED_VALUE"""),"2055-06-08T14:40:31.776158Z") -> 2055-06-08T14:40:31.776158Z | J2: =IFERROR(__xludf.DUMMYFUNCTION("""COMPUTED_VALUE"""),"2055-06-08T16:30:00Z") -> 2055-06-08T16:30:00Z | K2: =IFERROR(__xludf.DUMMYFUNCTION("""COMPUTED_VALUE"""),"2055-06-08T16:30:00Z") -> 2055-06-08T16:30:00Z | L2: =IFERROR(__xludf.DUMMYFUNCTION("""COMPUTED_VALUE"""),0) -> 0 | M2: =IFERROR(__xludf.DUMMYFUNCTION("""COMPUTED_VALUE"""),0) -> 0 | N2: =IFERROR(__xludf.DUMMYFUNCTION("""COMPUTED_VALUE"""),"2055-06-08T16:27:25.447059Z") -> 2055-06-08T16:27:25.447059Z | O2: =IFERROR(__xludf.DUMMYFUNCTION("""COMPUTED_VALUE"""),"2055-06-08T16:43:26.092195Z") -> 2055-06-08T16:43:26.092195Z | P2: =IFERROR(__xludf.DUMMYFUNCTION("""COMPUTED_VALUE"""),"2055-06-08T15:24:32.128072Z") -> 2055-06-08T15:24:32.128072Z | Q2: =IFERROR(__xludf.DUMMYFUNCTION("""COMPUTED_VALUE"""),1) -> 1 | R2: =IFERROR(__xludf.DUMMYFUNCTION("""COMPUTED_VALUE"""),"2055-06-08T15:24:56.562443Z") -> 2055-06-08T15:24:56.562443Z | U2: =IFERROR(__xludf.DUMMYFUNCTION("""COMPUTED_VALUE"""),56773) -> 56773 | V2: =IFERROR(__xludf.DUMMYFUNCTION("""COMPUTED_VALUE"""),4.5) -> 4.5 | W2: =IFERROR(__xludf.DUMMYFUNCTION("""COMPUTED_VALUE"""),3000) -> 3000 | X2: =IFERROR(__xludf.DUMMYFUNCTION("""COMPUTED_VALUE"""),4710) -> 4710 | AA2: =IFERROR(__xludf.DUMMYFUNCTION("""COMPUTED_VALUE"""),961) -> 961 | AB2: =IFERROR(__xludf.DUMMYFUNCTION("""COMPUTED_VALUE"""),0) -> 0 | AC2: =IFERROR(__xludf.DUMMYFUNCTION("""COMPUTED_VALUE"""),47) -> 47 | AE2: =IFERROR(__xludf.DUMMYFUNCTION("""COMPUTED_VALUE"""),"2055-06-08T12:27:25.447059Z") -> 2055-06-08T12:27:25.447059Z | AF2: =IFERROR(__xludf.DUMMYFUNCTION("""COMPUTED_VALUE"""),"2055-06-08T12:43:26.092195Z") -> 2055-06-08T12:43:26.092195Z | AG2: =IFERROR(__xludf.DUMMYFUNCTION("""COMPUTED_VALUE"""),"2055-06-08T11:24:32.128072Z") -> 2055-06-08T11:24:32.128072Z | AI2: =IFERROR(__xludf.DUMMYFUNCTION("""COMPUTED_VALUE"""),4.7) -> 4.7 | AJ2: =IFERROR(__xludf.DUMMYFUNCTION("""COMPUTED_VALUE"""),1261) -> 1261 | AK2: =IFERROR(__xludf.DUMMYFUNCTION("""COMPUTED_VALUE"""),3264) -> 3264 | AL2: =IFERROR(__xludf.DUMMYFUNCTION("""COMPUTED_VALUE"""),232) -> 232
A3: =IFERROR(__xludf.DUMMYFUNCTION("""COMPUTED_VALUE"""),371) -> 371 | C3: =IFERROR(__xludf.DUMMYFUNCTION("""COMPUTED_VALUE"""),4001) -> 4001 | D3: =IFERROR(__xludf.DUMMYFUNCTION("""COMPUTED_VALUE"""),"Dashattan") -> Dashattan | E3: =IFERROR(__xludf.DUMMYFUNCTION("""COMPUTED_VALUE"""),"Galaxy A") -> Galaxy A | F3: =IFERROR(__xludf.DUMMYFUNCTION("""COMPUTED_VALUE"""),"Arya") -> Arya | G3: =IFERROR(__xludf.DUMMYFUNCTION("""COMPUTED_VALUE"""),0) -> 0 | H3: =IFERROR(__xludf.DUMMYFUNCTION("""COMPUTED_VALUE"""),"bicycle") -> bicycle | I3: =IFERROR(__xludf.DUMMYFUNCTION("""COMPUTED_VALUE"""),"2055-06-03T23:55:23.345361Z") -> 2055-06-03T23:55:23.345361Z | J3: =IFERROR(__xludf.DUMMYFUNCTION("""COMPUTED_VALUE"""),"2055-06-04T02:10:19.438Z") -> 2055-06-04T02:10:19.438Z | K3: =IFERROR(__xludf.DUMMYFUNCTION("""COMPUTED_VALUE"""),"2055-06-04T01:42:06.438Z") -> 2055-06-04T01:42:06.438Z | L3: =IFERROR(__xludf.DUMMYFUNCTION("""COMPUTED_VALUE"""),1) -> 1 | M3: =IFERROR(__xludf.DUMMYFUNCTION("""COMPUTED_VALUE"""),0) -> 0 | N3: =IFERROR(__xludf.DUMMYFUNCTION("""COMPUTED_VALUE"""),"2055-06-04T00:43:45.908174Z") -> 2055-06-04T00:43:45.908174Z | O3: =IFERROR(__xludf.DUMMYFUNCTION("""COMPUTED_VALUE"""),"2055-06-04T01:08:26.640633Z") -> 2055-06-04T01:08:26.640633Z | P3: =IFERROR(__xludf.DUMMYFUNCTION("""COMPUTED_VALUE"""),"2055-06-04T00:30:14.629493Z") -> 2055-06-04T00:30:14.629493Z | Q3: =IFERROR(__xludf.DUMMYFUNCTION("""COMPUTED_VALUE"""),1) -> 1 | R3: =IFERROR(__xludf.DUMMYFUNCTION("""COMPUTED_VALUE"""),"2055-06-04T00:30:30.006106Z") -> 2055-06-04T00:30:30.006106Z | S3: =IFERROR(__xludf.DUMMYFUNCTION("""COMPUTED_VALUE"""),"2055-06-04T00:38:02.90308Z") -> 2055-06-04T00:38:02.90308Z | U3: =IFERROR(__xludf.DUMMYFUNCTION("""COMPUTED_VALUE"""),56768) -> 56768 | V3: =IFERROR(__xludf.DUMMYFUNCTION("""COMPUTED_VALUE"""),3.198404529) -> 3.1984045 | W3: =IFERROR(__xludf.DUMMYFUNCTION("""COMPUTED_VALUE"""),2000) -> 2000 | X3: =IFERROR(__xludf.DUMMYFUNCTION("""COMPUTED_VALUE"""),2276) -> 2276 | Y3: =IFERROR(__xludf.DUMMYFUNCTION("""COMPUTED_VALUE"""),452) -> 452 | Z3: =IFERROR(__xludf.DUMMYFUNCTION("""COMPUTED_VALUE"""),343) -> 343 | AA3: =IFERROR(__xludf.DUMMYFUNCTION("""COMPUTED_VALUE"""),1481) -> 1481 | AB3: =IFERROR(__xludf.DUMMYFUNCTION("""COMPUTED_VALUE"""),0) -> 0 | AC3: =IFERROR(__xludf.DUMMYFUNCTION("""COMPUTED_VALUE"""),10) -> 10 | AD3: =IFERROR(__xludf.DUMMYFUNCTION("""COMPUTED_VALUE"""),"early") -> early | AE3: =IFERROR(__xludf.DUMMYFUNCTION("""COMPUTED_VALUE"""),"2055-06-03T20:43:45.908174Z") -> 2055-06-03T20:43:45.908174Z | AF3: =IFERROR(__xludf.DUMMYFUNCTION("""COMPUTED_VALUE"""),"2055-06-03T21:08:26.640633Z") -> 2055-06-03T21:08:26.640633Z | AG3: =IFERROR(__xludf.DUMMYFUNCTION("""COMPUTED_VALUE"""),"2055-06-03T20:30:14.629493Z") -> 2055-06-03T20:30:14.629493Z | AH3: =IFERROR(__xludf.DUMMYFUNCTION("""COMPUTED_VALUE"""),"2055-06-03T20:38:02.90308Z") -> 2055-06-03T20:38:02.90308Z | AI3: =IFERROR(__xludf.DUMMYFUNCTION("""COMPUTED_VALUE"""),4.17) -> 4.17 | AJ3: =IFERROR(__xludf.DUMMYFUNCTION("""COMPUTED_VALUE"""),457) -> 457 | AK3: =IFERROR(__xludf.DUMMYFUNCTION("""COMPUTED_VALUE"""),1599) -> 1599
A4: =IFERROR(__xludf.DUMMYFUNCTION("""COMPUTED_VALUE"""),1012) -> 1012 | B4: =IFERROR(__xludf.DUMMYFUNCTION("""COMPUTED_VALUE"""),5) -> 5 | C4: =IFERROR(__xludf.DUMMYFUNCTION("""COMPUTED_VALUE"""),4001) -> 4001 | D4: =IFERROR(__xludf.DUMMYFUNCTION("""COMPUTED_VALUE"""),"Dashattan") -> Dashattan | E4: =IFERROR(__xludf.DUMMYFUNCTION("""COMPUTED_VALUE"""),"Galaxy A") -> Galaxy A | F4: =IFERROR(__xludf.DUMMYFUNCTION("""COMPUTED_VALUE"""),"Bret") -> Bret | G4: =IFERROR(__xludf.DUMMYFUNCTION("""COMPUTED_VALUE"""),0) -> 0 | H4: =IFERROR(__xludf.DUMMYFUNCTION("""COMPUTED_VALUE"""),"car") -> car | I4: =IFERROR(__xludf.DUMMYFUNCTION("""COMPUTED_VALUE"""),"2055-06-09T13:45:44.022432Z") -> 2055-06-09T13:45:44.022432Z | J4: =IFERROR(__xludf.DUMMYFUNCTION("""COMPUTED_VALUE"""),"2055-06-09T15:29:57.082Z") -> 2055-06-09T15:29:57.082Z | K4: =IFERROR(__xludf.DUMMYFUNCTION("""COMPUTED_VALUE"""),"2055-06-09T15:01:44.082Z") -> 2055-06-09T15:01:44.082Z | L4: =IFERROR(__xludf.DUMMYFUNCTION("""COMPUTED_VALUE"""),1) -> 1 | M4: =IFERROR(__xludf.DUMMYFUNCTION("""COMPUTED_VALUE"""),1) -> 1 | N4: =IFERROR(__xludf.DUMMYFUNCTION("""COMPUTED_VALUE"""),"2055-06-09T15:11:25.372168Z") -> 2055-06-09T15:11:25.372168Z | O4: =IFERROR(__xludf.DUMMYFUNCTION("""COMPUTED_VALUE"""),"2055-06-09T15:13:35.539122Z") -> 2055-06-09T15:13:35.539122Z | P4: =IFERROR(__xludf.DUMMYFUNCTION("""COMPUTED_VALUE"""),"2055-06-09T14:04:34.144994Z") -> 2055-06-09T14:04:34.144994Z | Q4: =IFERROR(__xludf.DUMMYFUNCTION("""COMPUTED_VALUE"""),0) -> 0 | R4: =IFERROR(__xludf.DUMMYFUNCTION("""COMPUTED_VALUE"""),"2055-06-09T14:05:28.008027Z") -> 2055-06-09T14:05:28.008027Z | S4: =IFERROR(__xludf.DUMMYFUNCTION("""COMPUTED_VALUE"""),"2055-06-09T14:19:12.351423Z") -> 2055-06-09T14:19:12.351423Z | U4: =IFERROR(__xludf.DUMMYFUNCTION("""COMPUTED_VALUE"""),56774) -> 56774 | V4: =IFERROR(__xludf.DUMMYFUNCTION("""COMPUTED_VALUE"""),4.5) -> 4.5 | W4: =IFERROR(__xludf.DUMMYFUNCTION("""COMPUTED_VALUE"""),1500) -> 1500 | X4: =IFERROR(__xludf.DUMMYFUNCTION("""COMPUTED_VALUE"""),4087) -> 4087 | Y4: =IFERROR(__xludf.DUMMYFUNCTION("""COMPUTED_VALUE"""),824) -> 824 | Z4: =IFERROR(__xludf.DUMMYFUNCTION("""COMPUTED_VALUE"""),3133) -> 3133 | AA4: =IFERROR(__xludf.DUMMYFUNCTION("""COMPUTED_VALUE"""),130) -> 130 | AB4: =IFERROR(__xludf.DUMMYFUNCTION("""COMPUTED_VALUE"""),0) -> 0 | AC4: =IFERROR(__xludf.DUMMYFUNCTION("""COMPUTED_VALUE"""),22) -> 22 | AD4: =IFERROR(__xludf.DUMMYFUNCTION("""COMPUTED_VALUE"""),"late") -> late | AE4: =IFERROR(__xludf.DUMMYFUNCTION("""COMPUTED_VALUE"""),"2055-06-09T11:11:25.372168Z") -> 2055-06-09T11:11:25.372168Z | AF4: =IFERROR(__xludf.DUMMYFUNCTION("""COMPUTED_VALUE"""),"2055-06-09T11:13:35.539122Z") -> 2055-06-09T11:13:35.539122Z | AG4: =IFERROR(__xludf.DUMMYFUNCTION("""COMPUTED_VALUE"""),"2055-06-09T10:04:34.144994Z") -> 2055-06-09T10:04:34.144994Z | AH4: =IFERROR(__xludf.DUMMYFUNCTION("""COMPUTED_VALUE"""),"2055-06-09T10:19:12.351423Z") -> 2055-06-09T10:19:12.351423Z | AI4: =IFERROR(__xludf.DUMMYFUNCTION("""COMPUTED_VALUE"""),3.82) -> 3.82 | AJ4: =IFERROR(__xludf.DUMMYFUNCTION("""COMPUTED_VALUE"""),174) -> 174 | AK4: =IFERROR(__xludf.DUMMYFUNCTION("""COMPUTED_VALUE"""),773) -> 773
A5: =IFERROR(__xludf.DUMMYFUNCTION("""COMPUTED_VALUE"""),774) -> 774 | C5: =IFERROR(__xludf.DUMMYFUNCTION("""COMPUTED_VALUE"""),4001) -> 4001 | D5: =IFERROR(__xludf.DUMMYFUNCTION("""COMPUTED_VALUE"""),"Dashattan") -> Dashattan | E5: =IFERROR(__xludf.DUMMYFUNCTION("""COMPUTED_VALUE"""),"Galaxy A") -> Galaxy A | F5: =IFERROR(__xludf.DUMMYFUNCTION("""COMPUTED_VALUE"""),"Bret") -> Bret | G5: =IFERROR(__xludf.DUMMYFUNCTION("""COMPUTED_VALUE"""),0) -> 0 | H5: =IFERROR(__xludf.DUMMYFUNCTION("""COMPUTED_VALUE"""),"car") -> car | I5: =IFERROR(__xludf.DUMMYFUNCTION("""COMPUTED_VALUE"""),"2055-06-06T22:14:59.221376Z") -> 2055-06-06T22:14:59.221376Z | J5: =IFERROR(__xludf.DUMMYFUNCTION("""COMPUTED_VALUE"""),"2055-06-07T15:45:00Z") -> 2055-06-07T15:45:00Z | K5: =IFERROR(__xludf.DUMMYFUNCTION("""COMPUTED_VALUE"""),"2055-06-07T15:45:00Z") -> 2055-06-07T15:45:00Z | L5: =IFERROR(__xludf.DUMMYFUNCTION("""COMPUTED_VALUE"""),0) -> 0 | M5: =IFERROR(__xludf.DUMMYFUNCTION("""COMPUTED_VALUE"""),0) -> 0 | N5: =IFERROR(__xludf.DUMMYFUNCTION("""COMPUTED_VALUE"""),"2055-06-07T15:35:32.652626Z") -> 2055-06-07T15:35:32.652626Z | O5: =IFERROR(__xludf.DUMMYFUNCTION("""COMPUTED_VALUE"""),"2055-06-07T15:50:01.734136Z") -> 2055-06-07T15:50:01.734136Z | P5: =IFERROR(__xludf.DUMMYFUNCTION("""COMPUTED_VALUE"""),"2055-06-07T14:40:24.824381Z") -> 2055-06-07T14:40:24.824381Z | Q5: =IFERROR(__xludf.DUMMYFUNCTION("""COMPUTED_VALUE"""),1) -> 1 | R5: =IFERROR(__xludf.DUMMYFUNCTION("""COMPUTED_VALUE"""),"2055-06-07T14:41:19.172553Z") -> 2055-06-07T14:41:19.172553Z | S5: =IFERROR(__xludf.DUMMYFUNCTION("""COMPUTED_VALUE"""),"2055-06-07T15:33:47.403919Z") -> 2055-06-07T15:33:47.403919Z | U5: =IFERROR(__xludf.DUMMYFUNCTION("""COMPUTED_VALUE"""),56772) -> 56772 | V5: =IFERROR(__xludf.DUMMYFUNCTION("""COMPUTED_VALUE"""),4.542521796) -> 4.5425218 | W5: =IFERROR(__xludf.DUMMYFUNCTION("""COMPUTED_VALUE"""),1500) -> 1500 | X5: =IFERROR(__xludf.DUMMYFUNCTION("""COMPUTED_VALUE"""),4122) -> 4122 | Y5: =IFERROR(__xludf.DUMMYFUNCTION("""COMPUTED_VALUE"""),3148) -> 3148 | Z5: =IFERROR(__xludf.DUMMYFUNCTION("""COMPUTED_VALUE"""),105) -> 105 | AA5: =IFERROR(__xludf.DUMMYFUNCTION("""COMPUTED_VALUE"""),869) -> 869 | AB5: =IFERROR(__xludf.DUMMYFUNCTION("""COMPUTED_VALUE"""),1) -> 1 | AC5: =IFERROR(__xludf.DUMMYFUNCTION("""COMPUTED_VALUE"""),32) -> 32 | AE5: =IFERROR(__xludf.DUMMYFUNCTION("""COMPUTED_VALUE"""),"2055-06-07T11:35:32.652626Z") -> 2055-06-07T11:35:32.652626Z | AF5: =IFERROR(__xludf.DUMMYFUNCTION("""COMPUTED_VALUE"""),"2055-06-07T11:50:01.734136Z") -> 2055-06-07T11:50:01.734136Z | AG5: =IFERROR(__xludf.DUMMYFUNCTION("""COMPUTED_VALUE"""),"2055-06-07T10:40:24.824381Z") -> 2055-06-07T10:40:24.824381Z | AH5: =IFERROR(__xludf.DUMMYFUNCTION("""COMPUTED_VALUE"""),"2055-06-07T11:33:47.403919Z") -> 2055-06-07T11:33:47.403919Z | AI5: =IFERROR(__xludf.DUMMYFUNCTION("""COMPUTED_VALUE"""),3.82) -> 3.82 | AJ5: =IFERROR(__xludf.DUMMYFUNCTION("""COMPUTED_VALUE"""),174) -> 174 | AK5: =IFERROR(__xludf.DUMMYFUNCTION("""COMPUTED_VALUE"""),773) -> 773
A6: =IFERROR(__xludf.DUMMYFUNCTION("""COMPUTED_VALUE"""),412) -> 412 | B6: =IFERROR(__xludf.DUMMYFUNCTION("""COMPUTED_VALUE"""),1) -> 1 | C6: =IFERROR(__xludf.DUMMYFUNCTION("""COMPUTED_VALUE"""),4001) -> 4001 | D6: =IFERROR(__xludf.DUMMYFUNCTION("""COMPUTED_VALUE"""),"Dashattan") -> Dashattan | E6: =IFERROR(__xludf.DUMMYFUNCTION("""COMPUTED_VALUE"""),"Galaxy A") -> Galaxy A | F6: =IFERROR(__xludf.DUMMYFUNCTION("""COMPUTED_VALUE"""),"Samm") -> Samm | G6: =IFERROR(__xludf.DUMMYFUNCTION("""COMPUTED_VALUE"""),0) -> 0 | H6: =IFERROR(__xludf.DUMMYFUNCTION("""COMPUTED_VALUE"""),"car") -> car | I6: =IFERROR(__xludf.DUMMYFUNCTION("""COMPUTED_VALUE"""),"2055-06-04T16:09:11.472458Z") -> 2055-06-04T16:09:11.472458Z | J6: =IFERROR(__xludf.DUMMYFUNCTION("""COMPUTED_VALUE"""),"2055-06-04T18:20:18.559Z") -> 2055-06-04T18:20:18.559Z | K6: =IFERROR(__xludf.DUMMYFUNCTION("""COMPUTED_VALUE"""),"2055-06-04T18:20:18.559Z") -> 2055-06-04T18:20:18.559Z | L6: =IFERROR(__xludf.DUMMYFUNCTION("""COMPUTED_VALUE"""),0) -> 0 | M6: =IFERROR(__xludf.DUMMYFUNCTION("""COMPUTED_VALUE"""),0) -> 0 | N6: =IFERROR(__xludf.DUMMYFUNCTION("""COMPUTED_VALUE"""),"2055-06-04T18:12:59.656413Z") -> 2055-06-04T18:12:59.656413Z | O6: =IFERROR(__xludf.DUMMYFUNCTION("""COMPUTED_VALUE"""),"2055-06-04T18:35:17.08753Z") -> 2055-06-04T18:35:17.08753Z | P6: =IFERROR(__xludf.DUMMYFUNCTION("""COMPUTED_VALUE"""),"2055-06-04T17:41:54.272943Z") -> 2055-06-04T17:41:54.272943Z | Q6: =IFERROR(__xludf.DUMMYFUNCTION("""COMPUTED_VALUE"""),1) -> 1 | R6: =IFERROR(__xludf.DUMMYFUNCTION("""COMPUTED_VALUE"""),"2055-06-04T17:42:13.505934Z") -> 2055-06-04T17:42:13.505934Z | S6: =IFERROR(__xludf.DUMMYFUNCTION("""COMPUTED_VALUE"""),"2055-06-04T17:58:03.42043Z") -> 2055-06-04T17:58:03.42043Z | U6: =IFERROR(__xludf.DUMMYFUNCTION("""COMPUTED_VALUE"""),56769) -> 56769 | V6: =IFERROR(__xludf.DUMMYFUNCTION("""COMPUTED_VALUE"""),4.3) -> 4.3 | W6: =IFERROR(__xludf.DUMMYFUNCTION("""COMPUTED_VALUE"""),1500) -> 1500 | X6: =IFERROR(__xludf.DUMMYFUNCTION("""COMPUTED_VALUE"""),3184) -> 3184 | Y6: =IFERROR(__xludf.DUMMYFUNCTION("""COMPUTED_VALUE"""),950) -> 950 | Z6: =IFERROR(__xludf.DUMMYFUNCTION("""COMPUTED_VALUE"""),896) -> 896 | AA6: =IFERROR(__xludf.DUMMYFUNCTION("""COMPUTED_VALUE"""),1338) -> 1338 | AB6: =IFERROR(__xludf.DUMMYFUNCTION("""COMPUTED_VALUE"""),0) -> 0 | AC6: =IFERROR(__xludf.DUMMYFUNCTION("""COMPUTED_VALUE"""),26) -> 26 | AD6: =IFERROR(__xludf.DUMMYFUNCTION("""COMPUTED_VALUE"""),"early") -> early | AE6: =IFERROR(__xludf.DUMMYFUNCTION("""COMPUTED_VALUE"""),"2055-06-04T14:12:59.656413Z") -> 2055-06-04T14:12:59.656413Z | AF6: =IFERROR(__xludf.DUMMYFUNCTION("""COMPUTED_VALUE"""),"2055-06-04T14:35:17.08753Z") -> 2055-06-04T14:35:17.08753Z | AG6: =IFERROR(__xludf.DUMMYFUNCTION("""COMPUTED_VALUE"""),"2055-06-04T13:41:54.272943Z") -> 2055-06-04T13:41:54.272943Z | AH6: =IFERROR(__xludf.DUMMYFUNCTION("""COMPUTED_VALUE"""),"2055-06-04T13:58:03.42043Z") -> 2055-06-04T13:58:03.42043Z | AI6: =IFERROR(__xludf.DUMMYFUNCTION("""COMPUTED_VALUE"""),4.03) -> 4.03 | AJ6: =IFERROR(__xludf.DUMMYFUNCTION("""COMPUTED_VALUE"""),505) -> 505 | AK6: =IFERROR(__xludf.DUMMYFUNCTION("""COMPUTED_VALUE"""),1721) -> 1721 | AL6: =IFERROR(__xludf.DUMMYFUNCTION("""COMPUTED_VALUE"""),457) -> 457
A7: =IFERROR(__xludf.DUMMYFUNCTION("""COMPUTED_VALUE"""),1050) -> 1050 | B7: =IFERROR(__xludf.DUMMYFUNCTION("""COMPUTED_VALUE"""),1) -> 1 | C7: =IFERROR(__xludf.DUMMYFUNCTION("""COMPUTED_VALUE"""),4001) -> 4001 | D7: =IFERROR(__xludf.DUMMYFUNCTION("""COMPUTED_VALUE"""),"Dashattan") -> Dashattan | E7: =IFERROR(__xludf.DUMMYFUNCTION("""COMPUTED_VALUE"""),"Galaxy A") -> Galaxy A | F7: =IFERROR(__xludf.DUMMYFUNCTION("""COMPUTED_VALUE"""),"Carlee") -> Carlee | G7: =IFERROR(__xludf.DUMMYFUNCTION("""COMPUTED_VALUE"""),0) -> 0 | H7: =IFERROR(__xludf.DUMMYFUNCTION("""COMPUTED_VALUE"""),"car") -> car | I7: =IFERROR(__xludf.DUMMYFUNCTION("""COMPUTED_VALUE"""),"2055-06-09T19:49:41.693256Z") -> 2055-06-09T19:49:41.693256Z | J7: =IFERROR(__xludf.DUMMYFUNCTION("""COMPUTED_VALUE"""),"2055-06-10T15:45:00Z") -> 2055-06-10T15:45:00Z | K7: =IFERROR(__xludf.DUMMYFUNCTION("""COMPUTED_VALUE"""),"2055-06-10T15:45:00Z") -> 2055-06-10T15:45:00Z | L7: =IFERROR(__xludf.DUMMYFUNCTION("""COMPUTED_VALUE"""),0) -> 0 | M7: =IFERROR(__xludf.DUMMYFUNCTION("""COMPUTED_VALUE"""),0) -> 0 | N7: =IFERROR(__xludf.DUMMYFUNCTION("""COMPUTED_VALUE"""),"2055-06-10T15:18:09.540509Z") -> 2055-06-10T15:18:09.540509Z | O7: =IFERROR(__xludf.DUMMYFUNCTION("""COMPUTED_VALUE"""),"2055-06-10T15:23:08.754428Z") -> 2055-06-10T15:23:08.754428Z | P7: =IFERROR(__xludf.DUMMYFUNCTION("""COMPUTED_VALUE"""),"2055-06-10T14:47:54.187365Z") -> 2055-06-10T14:47:54.187365Z | Q7: =IFERROR(__xludf.DUMMYFUNCTION("""COMPUTED_VALUE"""),0) -> 0 | R7: =IFERROR(__xludf.DUMMYFUNCTION("""COMPUTED_VALUE"""),"2055-06-10T14:48:06.628086Z") -> 2055-06-10T14:48:06.628086Z | S7: =IFERROR(__xludf.DUMMYFUNCTION("""COMPUTED_VALUE"""),"2055-06-10T15:10:46.951495Z") -> 2055-06-10T15:10:46.951495Z | U7: =IFERROR(__xludf.DUMMYFUNCTION("""COMPUTED_VALUE"""),56775) -> 56775 | V7: =IFERROR(__xludf.DUMMYFUNCTION("""COMPUTED_VALUE"""),4.542521796) -> 4.5425218 | W7: =IFERROR(__xludf.DUMMYFUNCTION("""COMPUTED_VALUE"""),1500) -> 1500 | X7: =IFERROR(__xludf.DUMMYFUNCTION("""COMPUTED_VALUE"""),2102) -> 2102 | Y7: =IFERROR(__xludf.DUMMYFUNCTION("""COMPUTED_VALUE"""),1360) -> 1360 | Z7: =IFERROR(__xludf.DUMMYFUNCTION("""COMPUTED_VALUE"""),443) -> 443 | AA7: =IFERROR(__xludf.DUMMYFUNCTION("""COMPUTED_VALUE"""),299) -> 299 | AB7: =IFERROR(__xludf.DUMMYFUNCTION("""COMPUTED_VALUE"""),0) -> 0 | AC7: =IFERROR(__xludf.DUMMYFUNCTION("""COMPUTED_VALUE"""),20) -> 20 | AD7: =IFERROR(__xludf.DUMMYFUNCTION("""COMPUTED_VALUE"""),"late") -> late | AE7: =IFERROR(__xludf.DUMMYFUNCTION("""COMPUTED_VALUE"""),"2055-06-10T11:18:09.540509Z") -> 2055-06-10T11:18:09.540509Z | AF7: =IFERROR(__xludf.DUMMYFUNCTION("""COMPUTED_VALUE"""),"2055-06-10T11:23:08.754428Z") -> 2055-06-10T11:23:08.754428Z | AG7: =IFERROR(__xludf.DUMMYFUNCTION("""COMPUTED_VALUE"""),"2055-06-10T10:47:54.187365Z") -> 2055-06-10T10:47:54.187365Z | AH7: =IFERROR(__xludf.DUMMYFUNCTION("""COMPUTED_VALUE"""),"2055-06-10T11:10:46.951495Z") -> 2055-06-10T11:10:46.951495Z | AI7: =IFERROR(__xludf.DUMMYFUNCTION("""COMPUTED_VALUE"""),4.52) -> 4.52 | AJ7: =IFERROR(__xludf.DUMMYFUNCTION("""COMPUTED_VALUE"""),269) -> 269 | AK7: =IFERROR(__xludf.DUMMYFUNCTION("""COMPUTED_VALUE"""),895) -> 895 | AL7: =IFERROR(__xludf.DUMMYFUNCTION("""COMPUTED_VALUE"""),23) -> 23
A8: =IFERROR(__xludf.DUMMYFUNCTION("""COMPUTED_VALUE"""),5) -> 5 | B8: =IFERROR(__xludf.DUMMYFUNCTION("""COMPUTED_VALUE"""),5) -> 5 | C8: =IFERROR(__xludf.DUMMYFUNCTION("""COMPUTED_VALUE"""),4050) -> 4050 | D8: =IFERROR(__xludf.DUMMYFUNCTION("""COMPUTED_VALUE"""),"Doorlanta") -> Doorlanta | E8: =IFERROR(__xludf.DUMMYFUNCTION("""COMPUTED_VALUE"""),"Galaxy A") -> Galaxy A | F8: =IFERROR(__xludf.DUMMYFUNCTION("""COMPUTED_VALUE"""),"Jagar") -> Jagar | G8: =IFERROR(__xludf.DUMMYFUNCTION("""COMPUTED_VALUE"""),0) -> 0 | H8: =IFERROR(__xludf.DUMMYFUNCTION("""COMPUTED_VALUE"""),"car") -> car | I8: =IFERROR(__xludf.DUMMYFUNCTION("""COMPUTED_VALUE"""),"2055-06-01T14:26:36.995622Z") -> 2055-06-01T14:26:36.995622Z | J8: =IFERROR(__xludf.DUMMYFUNCTION("""COMPUTED_VALUE"""),"2055-06-01T16:00:00Z") -> 2055-06-01T16:00:00Z | K8: =IFERROR(__xludf.DUMMYFUNCTION("""COMPUTED_VALUE"""),"2055-06-01T16:00:00Z") -> 2055-06-01T16:00:00Z | L8: =IFERROR(__xludf.DUMMYFUNCTION("""COMPUTED_VALUE"""),0) -> 0 | M8: =IFERROR(__xludf.DUMMYFUNCTION("""COMPUTED_VALUE"""),0) -> 0 | N8: =IFERROR(__xludf.DUMMYFUNCTION("""COMPUTED_VALUE"""),"2055-06-01T15:41:52.41593Z") -> 2055-06-01T15:41:52.41593Z | O8: =IFERROR(__xludf.DUMMYFUNCTION("""COMPUTED_VALUE"""),"2055-06-01T15:52:44.442115Z") -> 2055-06-01T15:52:44.442115Z | P8: =IFERROR(__xludf.DUMMYFUNCTION("""COMPUTED_VALUE"""),"2055-06-01T15:00:07.376028Z") -> 2055-06-01T15:00:07.376028Z | Q8: =IFERROR(__xludf.DUMMYFUNCTION("""COMPUTED_VALUE"""),0) -> 0 | R8: =IFERROR(__xludf.DUMMYFUNCTION("""COMPUTED_VALUE"""),"2055-06-01T15:00:16.289572Z") -> 2055-06-01T15:00:16.289572Z | S8: =IFERROR(__xludf.DUMMYFUNCTION("""COMPUTED_VALUE"""),"2055-06-01T15:11:29.739589Z") -> 2055-06-01T15:11:29.739589Z | U8: =IFERROR(__xludf.DUMMYFUNCTION("""COMPUTED_VALUE"""),56766) -> 56766 | V8: =IFERROR(__xludf.DUMMYFUNCTION("""COMPUTED_VALUE"""),4.6) -> 4.6 | W8: =IFERROR(__xludf.DUMMYFUNCTION("""COMPUTED_VALUE"""),1500) -> 1500 | X8: =IFERROR(__xludf.DUMMYFUNCTION("""COMPUTED_VALUE"""),3148) -> 3148 | Y8: =IFERROR(__xludf.DUMMYFUNCTION("""COMPUTED_VALUE"""),673) -> 673 | Z8: =IFERROR(__xludf.DUMMYFUNCTION("""COMPUTED_VALUE"""),1823) -> 1823 | AA8: =IFERROR(__xludf.DUMMYFUNCTION("""COMPUTED_VALUE"""),652) -> 652 | AB8: =IFERROR(__xludf.DUMMYFUNCTION("""COMPUTED_VALUE"""),0) -> 0 | AC8: =IFERROR(__xludf.DUMMYFUNCTION("""COMPUTED_VALUE"""),15) -> 15 | AD8: =IFERROR(__xludf.DUMMYFUNCTION("""COMPUTED_VALUE"""),"early") -> early | AE8: =IFERROR(__xludf.DUMMYFUNCTION("""COMPUTED_VALUE"""),"2055-06-01T11:41:52.41593Z") -> 2055-06-01T11:41:52.41593Z | AF8: =IFERROR(__xludf.DUMMYFUNCTION("""COMPUTED_VALUE"""),"2055-06-01T11:52:44.442115Z") -> 2055-06-01T11:52:44.442115Z | AG8: =IFERROR(__xludf.DUMMYFUNCTION("""COMPUTED_VALUE"""),"2055-06-01T11:00:07.376028Z") -> 2055-06-01T11:00:07.376028Z | AH8: =IFERROR(__xludf.DUMMYFUNCTION("""COMPUTED_VALUE"""),"2055-06-01T11:11:29.739589Z") -> 2055-06-01T11:11:29.739589Z | AI8: =IFERROR(__xludf.DUMMYFUNCTION("""COMPUTED_VALUE"""),4.89) -> 4.89 | AJ8: =IFERROR(__xludf.DUMMYFUNCTION("""COMPUTED_VALUE"""),1778) -> 1778 | AK8: =IFERROR(__xludf.DUMMYFUNCTION("""COMPUTED_VALUE"""),5138) -> 5138 | AL8: =IFERROR(__xludf.DUMMYFUNCTION("""COMPUTED_VALUE"""),314) -> 314
A9: =IFERROR(__xludf.DUMMYFUNCTION("""COMPUTED_VALUE"""),823) -> 823 | B9: =IFERROR(__xludf.DUMMYFUNCTION("""COMPUTED_VALUE"""),5) -> 5 | C9: =IFERROR(__xludf.DUMMYFUNCTION("""COMPUTED_VALUE"""),4001) -> 4001 | D9: =IFERROR(__xludf.DUMMYFUNCTION("""COMPUTED_VALUE"""),"Dashattan") -> Dashattan | E9: =IFERROR(__xludf.DUMMYFUNCTION("""COMPUTED_VALUE"""),"Galaxy A") -> Galaxy A | F9: =IFERROR(__xludf.DUMMYFUNCTION("""COMPUTED_VALUE"""),"Samm") -> Samm | G9: =IFERROR(__xludf.DUMMYFUNCTION("""COMPUTED_VALUE"""),0) -> 0 | H9: =IFERROR(__xludf.DUMMYFUNCTION("""COMPUTED_VALUE"""),"car") -> car | I9: =IFERROR(__xludf.DUMMYFUNCTION("""COMPUTED_VALUE"""),"2055-06-07T12:29:58.490584Z") -> 2055-06-07T12:29:58.490584Z | J9: =IFERROR(__xludf.DUMMYFUNCTION("""COMPUTED_VALUE"""),"2055-06-07T23:15:00Z") -> 2055-06-07T23:15:00Z | K9: =IFERROR(__xludf.DUMMYFUNCTION("""COMPUTED_VALUE"""),"2055-06-07T23:15:00Z") -> 2055-06-07T23:15:00Z | L9: =IFERROR(__xludf.DUMMYFUNCTION("""COMPUTED_VALUE"""),0) -> 0 | M9: =IFERROR(__xludf.DUMMYFUNCTION("""COMPUTED_VALUE"""),0) -> 0 | N9: =IFERROR(__xludf.DUMMYFUNCTION("""COMPUTED_VALUE"""),"2055-06-07T23:06:49.039195Z") -> 2055-06-07T23:06:49.039195Z | O9: =IFERROR(__xludf.DUMMYFUNCTION("""COMPUTED_VALUE"""),"2055-06-07T23:07:04.529095Z") -> 2055-06-07T23:07:04.529095Z | P9: =IFERROR(__xludf.DUMMYFUNCTION("""COMPUTED_VALUE"""),"2055-06-07T22:18:34.346697Z") -> 2055-06-07T22:18:34.346697Z | Q9: =IFERROR(__xludf.DUMMYFUNCTION("""COMPUTED_VALUE"""),0) -> 0 | R9: =IFERROR(__xludf.DUMMYFUNCTION("""COMPUTED_VALUE"""),"2055-06-07T22:18:39.784875Z") -> 2055-06-07T22:18:39.784875Z | S9: =IFERROR(__xludf.DUMMYFUNCTION("""COMPUTED_VALUE"""),"2055-06-07T22:33:52.326656Z") -> 2055-06-07T22:33:52.326656Z | U9: =IFERROR(__xludf.DUMMYFUNCTION("""COMPUTED_VALUE"""),56772) -> 56772 | V9: =IFERROR(__xludf.DUMMYFUNCTION("""COMPUTED_VALUE"""),3.242009848) -> 3.2420098 | W9: =IFERROR(__xludf.DUMMYFUNCTION("""COMPUTED_VALUE"""),1500) -> 1500 | X9: =IFERROR(__xludf.DUMMYFUNCTION("""COMPUTED_VALUE"""),2905) -> 2905 | Y9: =IFERROR(__xludf.DUMMYFUNCTION("""COMPUTED_VALUE"""),913) -> 913 | Z9: =IFERROR(__xludf.DUMMYFUNCTION("""COMPUTED_VALUE"""),1977) -> 1977 | AA9: =IFERROR(__xludf.DUMMYFUNCTION("""COMPUTED_VALUE"""),15) -> 15 | AB9: =IFERROR(__xludf.DUMMYFUNCTION("""COMPUTED_VALUE"""),0) -> 0 | AC9: =IFERROR(__xludf.DUMMYFUNCTION("""COMPUTED_VALUE"""),6) -> 6 | AD9: =IFERROR(__xludf.DUMMYFUNCTION("""COMPUTED_VALUE"""),"late") -> late | AE9: =IFERROR(__xludf.DUMMYFUNCTION("""COMPUTED_VALUE"""),"2055-06-07T19:06:49.039195Z") -> 2055-06-07T19:06:49.039195Z | AF9: =IFERROR(__xludf.DUMMYFUNCTION("""COMPUTED_VALUE"""),"2055-06-07T19:07:04.529095Z") -> 2055-06-07T19:07:04.529095Z | AG9: =IFERROR(__xludf.DUMMYFUNCTION("""COMPUTED_VALUE"""),"2055-06-07T18:18:34.346697Z") -> 2055-06-07T18:18:34.346697Z | AH9: =IFERROR(__xludf.DUMMYFUNCTION("""COMPUTED_VALUE"""),"2055-06-07T18:33:52.326656Z") -> 2055-06-07T18:33:52.326656Z | AI9: =IFERROR(__xludf.DUMMYFUNCTION("""COMPUTED_VALUE"""),4.03) -> 4.03 | AJ9: =IFERROR(__xludf.DUMMYFUNCTION("""COMPUTED_VALUE"""),505) -> 505 | AK9: =IFERROR(__xludf.DUMMYFUNCTION("""COMPUTED_VALUE"""),1721) -> 1721 | AL9: =IFERROR(__xludf.DUMMYFUNCTION("""COMPUTED_VALUE"""),457) -> 457
A10: =IFERROR(__xludf.DUMMYFUNCTION("""COMPUTED_VALUE"""),275) -> 275 | C10: =IFERROR(__xludf.DUMMYFUNCTION("""COMPUTED_VALUE"""),4001) -> 4001 | D10: =IFERROR(__xludf.DUMMYFUNCTION("""COMPUTED_VALUE"""),"Dashattan") -> Dashattan | E10: =IFERROR(__xludf.DUMMYFUNCTION("""COMPUTED_VALUE"""),"Galaxy A") -> Galaxy A | F10: =IFERROR(__xludf.DUMMYFUNCTION("""COMPUTED_VALUE"""),"Samm") -> Samm | G10: =IFERROR(__xludf.DUMMYFUNCTION("""COMPUTED_VALUE"""),0) -> 0 | H10: =IFERROR(__xludf.DUMMYFUNCTION("""COMPUTED_VALUE"""),"car") -> car | I10: =IFERROR(__xludf.DUMMYFUNCTION("""COMPUTED_VALUE"""),"2055-06-03T15:49:29.798239Z") -> 2055-06-03T15:49:29.798239Z | J10: =IFERROR(__xludf.DUMMYFUNCTION("""COMPUTED_VALUE"""),"2055-06-03T17:14:45.888Z") -> 2055-06-03T17:14:45.888Z | K10: =IFERROR(__xludf.DUMMYFUNCTION("""COMPUTED_VALUE"""),"2055-06-03T17:01:32.888Z") -> 2055-06-03T17:01:32.888Z | L10: =IFERROR(__xludf.DUMMYFUNCTION("""COMPUTED_VALUE"""),1) -> 1 | M10: =IFERROR(__xludf.DUMMYFUNCTION("""COMPUTED_VALUE"""),0) -> 0 | N10: =IFERROR(__xludf.DUMMYFUNCTION("""COMPUTED_VALUE"""),"2055-06-03T16:37:12.215405Z") -> 2055-06-03T16:37:12.215405Z | O10: =IFERROR(__xludf.DUMMYFUNCTION("""COMPUTED_VALUE"""),"2055-06-03T16:51:15.79938Z") -> 2055-06-03T16:51:15.79938Z | P10: =IFERROR(__xludf.DUMMYFUNCTION("""COMPUTED_VALUE"""),"2055-06-03T16:05:14.936934Z") -> 2055-06-03T16:05:14.936934Z | Q10: =IFERROR(__xludf.DUMMYFUNCTION("""COMPUTED_VALUE"""),0) -> 0 | R10: =IFERROR(__xludf.DUMMYFUNCTION("""COMPUTED_VALUE"""),"2055-06-03T16:05:22.620426Z") -> 2055-06-03T16:05:22.620426Z | S10: =IFERROR(__xludf.DUMMYFUNCTION("""COMPUTED_VALUE"""),"2055-06-03T16:32:42.302357Z") -> 2055-06-03T16:32:42.302357Z | U10: =IFERROR(__xludf.DUMMYFUNCTION("""COMPUTED_VALUE"""),56768) -> 56768 | V10: =IFERROR(__xludf.DUMMYFUNCTION("""COMPUTED_VALUE"""),4.6) -> 4.6 | W10: =IFERROR(__xludf.DUMMYFUNCTION("""COMPUTED_VALUE"""),1500) -> 1500 | X10: =IFERROR(__xludf.DUMMYFUNCTION("""COMPUTED_VALUE"""),2753) -> 2753 | Y10: =IFERROR(__xludf.DUMMYFUNCTION("""COMPUTED_VALUE"""),1640) -> 1640 | Z10: =IFERROR(__xludf.DUMMYFUNCTION("""COMPUTED_VALUE"""),270) -> 270 | AA10: =IFERROR(__xludf.DUMMYFUNCTION("""COMPUTED_VALUE"""),843) -> 843 | AB10: =IFERROR(__xludf.DUMMYFUNCTION("""COMPUTED_VALUE"""),0) -> 0 | AC10: =IFERROR(__xludf.DUMMYFUNCTION("""COMPUTED_VALUE"""),10) -> 10 | AD10: =IFERROR(__xludf.DUMMYFUNCTION("""COMPUTED_VALUE"""),"late") -> late | AE10: =IFERROR(__xludf.DUMMYFUNCTION("""COMPUTED_VALUE"""),"2055-06-03T12:37:12.215405Z") -> 2055-06-03T12:37:12.215405Z | AF10: =IFERROR(__xludf.DUMMYFUNCTION("""COMPUTED_VALUE"""),"2055-06-03T12:51:15.79938Z") -> 2055-06-03T12:51:15.79938Z | AG10: =IFERROR(__xludf.DUMMYFUNCTION("""COMPUTED_VALUE"""),"2055-06-03T12:05:14.936934Z") -> 2055-06-03T12:05:14.936934Z | AH10: =IFERROR(__xludf.DUMMYFUNCTION("""COMPUTED_VALUE"""),"2055-06-03T12:32:42.302357Z") -> 2055-06-03T12:32:42.302357Z | AI10: =IFERROR(__xludf.DUMMYFUNCTION("""COMPUTED_VALUE"""),4.03) -> 4.03 | AJ10: =IFERROR(__xludf.DUMMYFUNCTION("""COMPUTED_VALUE"""),505) -> 505 | AK10: =IFERROR(__xludf.DUMMYFUNCTION("""COMPUTED_VALUE"""),1721) -> 1721 | AL10: =IFERROR(__xludf.DUMMYFUNCTION("""COMPUTED_VALUE"""),457) -> 457
